2025-01-21 01:00:47,864 - distributed.nanny - INFO -         Start Nanny at: 'tcp://172.16.2.1:45369'
2025-01-21 01:00:47,883 - distributed.nanny - INFO -         Start Nanny at: 'tcp://172.16.2.1:43372'
2025-01-21 01:00:47,894 - distributed.nanny - INFO -         Start Nanny at: 'tcp://172.16.2.1:33624'
2025-01-21 01:00:47,895 - distributed.nanny - INFO -         Start Nanny at: 'tcp://172.16.2.1:40576'
2025-01-21 01:00:51,240 - distributed.worker - INFO -       Start worker at:     tcp://172.16.2.1:35066
2025-01-21 01:00:51,240 - distributed.worker - INFO -          Listening to:     tcp://172.16.2.1:35066
2025-01-21 01:00:51,240 - distributed.worker - INFO -           Worker name:           SLURMCluster-1-2
2025-01-21 01:00:51,240 - distributed.worker - INFO -       Start worker at:     tcp://172.16.2.1:38501
2025-01-21 01:00:51,241 - distributed.worker - INFO -          dashboard at:           172.16.2.1:45640
2025-01-21 01:00:51,241 - distributed.worker - INFO -          Listening to:     tcp://172.16.2.1:38501
2025-01-21 01:00:51,241 - distributed.worker - INFO - Waiting to connect to: tcp://159.237.145.53:44251
2025-01-21 01:00:51,241 - distributed.worker - INFO -           Worker name:           SLURMCluster-1-0
2025-01-21 01:00:51,242 - distributed.worker - INFO - -------------------------------------------------
2025-01-21 01:00:51,242 - distributed.worker - INFO -          dashboard at:           172.16.2.1:35466
2025-01-21 01:00:51,242 - distributed.worker - INFO -               Threads:                          1
2025-01-21 01:00:51,242 - distributed.worker - INFO - Waiting to connect to: tcp://159.237.145.53:44251
2025-01-21 01:00:51,243 - distributed.worker - INFO -                Memory:                   7.45 GiB
2025-01-21 01:00:51,243 - distributed.worker - INFO - -------------------------------------------------
2025-01-21 01:00:51,243 - distributed.worker - INFO -       Local Directory: /tmp/dask-scratch-space/worker-z6tou09t
2025-01-21 01:00:51,243 - distributed.worker - INFO -               Threads:                          1
2025-01-21 01:00:51,244 - distributed.worker - INFO - -------------------------------------------------
2025-01-21 01:00:51,244 - distributed.worker - INFO -                Memory:                   7.45 GiB
2025-01-21 01:00:51,244 - distributed.worker - INFO -       Local Directory: /tmp/dask-scratch-space/worker-fn3g3xj3
2025-01-21 01:00:51,245 - distributed.worker - INFO - -------------------------------------------------
2025-01-21 01:00:51,256 - distributed.worker - INFO -       Start worker at:     tcp://172.16.2.1:39819
2025-01-21 01:00:51,256 - distributed.worker - INFO -          Listening to:     tcp://172.16.2.1:39819
2025-01-21 01:00:51,256 - distributed.worker - INFO -           Worker name:           SLURMCluster-1-3
2025-01-21 01:00:51,257 - distributed.worker - INFO -          dashboard at:           172.16.2.1:36306
2025-01-21 01:00:51,257 - distributed.worker - INFO - Waiting to connect to: tcp://159.237.145.53:44251
2025-01-21 01:00:51,257 - distributed.worker - INFO - -------------------------------------------------
2025-01-21 01:00:51,258 - distributed.worker - INFO -               Threads:                          1
2025-01-21 01:00:51,258 - distributed.worker - INFO -                Memory:                   7.45 GiB
2025-01-21 01:00:51,258 - distributed.worker - INFO -       Local Directory: /tmp/dask-scratch-space/worker-cebe3g7c
2025-01-21 01:00:51,258 - distributed.worker - INFO - -------------------------------------------------
2025-01-21 01:00:51,279 - distributed.worker - INFO -       Start worker at:     tcp://172.16.2.1:46673
2025-01-21 01:00:51,280 - distributed.worker - INFO -          Listening to:     tcp://172.16.2.1:46673
2025-01-21 01:00:51,280 - distributed.worker - INFO -           Worker name:           SLURMCluster-1-1
2025-01-21 01:00:51,280 - distributed.worker - INFO -          dashboard at:           172.16.2.1:45836
2025-01-21 01:00:51,281 - distributed.worker - INFO - Waiting to connect to: tcp://159.237.145.53:44251
2025-01-21 01:00:51,281 - distributed.worker - INFO - -------------------------------------------------
2025-01-21 01:00:51,281 - distributed.worker - INFO -               Threads:                          1
2025-01-21 01:00:51,282 - distributed.worker - INFO -                Memory:                   7.45 GiB
2025-01-21 01:00:51,282 - distributed.worker - INFO -       Local Directory: /tmp/dask-scratch-space/worker-5tp53k2e
2025-01-21 01:00:51,282 - distributed.worker - INFO - -------------------------------------------------
2025-01-21 01:00:53,088 - distributed.worker - INFO - Starting Worker plugin shuffle
2025-01-21 01:00:53,089 - distributed.worker - INFO -         Registered to: tcp://159.237.145.53:44251
2025-01-21 01:00:53,090 - distributed.worker - INFO - -------------------------------------------------
2025-01-21 01:00:53,091 - distributed.core - INFO - Starting established connection to tcp://159.237.145.53:44251
2025-01-21 01:00:53,222 - distributed.worker - INFO - Starting Worker plugin shuffle
2025-01-21 01:00:53,223 - distributed.worker - INFO -         Registered to: tcp://159.237.145.53:44251
2025-01-21 01:00:53,224 - distributed.worker - INFO - -------------------------------------------------
2025-01-21 01:00:53,224 - distributed.worker - INFO - Starting Worker plugin shuffle
2025-01-21 01:00:53,225 - distributed.core - INFO - Starting established connection to tcp://159.237.145.53:44251
2025-01-21 01:00:53,225 - distributed.worker - INFO -         Registered to: tcp://159.237.145.53:44251
2025-01-21 01:00:53,226 - distributed.worker - INFO - -------------------------------------------------
2025-01-21 01:00:53,227 - distributed.core - INFO - Starting established connection to tcp://159.237.145.53:44251
2025-01-21 01:00:53,228 - distributed.worker - INFO - Starting Worker plugin shuffle
2025-01-21 01:00:53,230 - distributed.worker - INFO -         Registered to: tcp://159.237.145.53:44251
2025-01-21 01:00:53,231 - distributed.worker - INFO - -------------------------------------------------
2025-01-21 01:00:53,231 - distributed.core - INFO - Starting established connection to tcp://159.237.145.53:44251
2025-01-21 01:20:36,029 - distributed.core - INFO - Event loop was unresponsive in Worker for 9.70s.  This is often caused by long-running GIL-holding functions or moving large chunks of data. This can cause timeouts and instability.
2025-01-21 01:20:36,030 - distributed.core - INFO - Event loop was unresponsive in Worker for 9.68s.  This is often caused by long-running GIL-holding functions or moving large chunks of data. This can cause timeouts and instability.
2025-01-21 01:20:36,030 - distributed.core - INFO - Event loop was unresponsive in Worker for 9.70s.  This is often caused by long-running GIL-holding functions or moving large chunks of data. This can cause timeouts and instability.
2025-01-21 01:20:36,030 - distributed.core - INFO - Event loop was unresponsive in Worker for 9.69s.  This is often caused by long-running GIL-holding functions or moving large chunks of data. This can cause timeouts and instability.
2025-01-21 04:40:34,034 - distributed.core - INFO - Event loop was unresponsive in Worker for 3.80s.  This is often caused by long-running GIL-holding functions or moving large chunks of data. This can cause timeouts and instability.
2025-01-21 04:40:45,681 - distributed.core - INFO - Event loop was unresponsive in Worker for 6.28s.  This is often caused by long-running GIL-holding functions or moving large chunks of data. This can cause timeouts and instability.
2025-01-21 05:13:25,399 - distributed.worker - ERROR - Failed to communicate with scheduler during heartbeat.
Traceback (most recent call last):
  File "/home/igarzonalva/.conda/envs/arboreto-env/lib/python3.10/site-packages/tornado/iostream.py", line 861, in _read_to_buffer
    bytes_read = self.read_from_fd(buf)
  File "/home/igarzonalva/.conda/envs/arboreto-env/lib/python3.10/site-packages/tornado/iostream.py", line 1116, in read_from_fd
    return self.socket.recv_into(buf, len(buf))
ConnectionResetError: [Errno 104] Connection reset by peer

The above exception was the direct cause of the following exception:

Traceback (most recent call last):
  File "/home/igarzonalva/.conda/envs/arboreto-env/lib/python3.10/site-packages/distributed/worker.py", line 1252, in heartbeat
    response = await retry_operation(
  File "/home/igarzonalva/.conda/envs/arboreto-env/lib/python3.10/site-packages/distributed/utils_comm.py", line 455, in retry_operation
    return await retry(
  File "/home/igarzonalva/.conda/envs/arboreto-env/lib/python3.10/site-packages/distributed/utils_comm.py", line 434, in retry
    return await coro()
  File "/home/igarzonalva/.conda/envs/arboreto-env/lib/python3.10/site-packages/distributed/core.py", line 1395, in send_recv_from_rpc
    return await send_recv(comm=comm, op=key, **kwargs)
  File "/home/igarzonalva/.conda/envs/arboreto-env/lib/python3.10/site-packages/distributed/core.py", line 1154, in send_recv
    response = await comm.read(deserializers=deserializers)
  File "/home/igarzonalva/.conda/envs/arboreto-env/lib/python3.10/site-packages/distributed/comm/tcp.py", line 236, in read
    convert_stream_closed_error(self, e)
  File "/home/igarzonalva/.conda/envs/arboreto-env/lib/python3.10/site-packages/distributed/comm/tcp.py", line 140, in convert_stream_closed_error
    raise CommClosedError(f"in {obj}: {exc.__class__.__name__}: {exc}") from exc
distributed.comm.core.CommClosedError: in <TCP (closed) ConnectionPool.heartbeat_worker local=tcp://172.16.2.1:34862 remote=tcp://159.237.145.53:44251>: ConnectionResetError: [Errno 104] Connection reset by peer
2025-01-21 05:13:25,399 - distributed.worker - ERROR - Failed to communicate with scheduler during heartbeat.
Traceback (most recent call last):
  File "/home/igarzonalva/.conda/envs/arboreto-env/lib/python3.10/site-packages/tornado/iostream.py", line 861, in _read_to_buffer
    bytes_read = self.read_from_fd(buf)
  File "/home/igarzonalva/.conda/envs/arboreto-env/lib/python3.10/site-packages/tornado/iostream.py", line 1116, in read_from_fd
    return self.socket.recv_into(buf, len(buf))
ConnectionResetError: [Errno 104] Connection reset by peer

The above exception was the direct cause of the following exception:

Traceback (most recent call last):
  File "/home/igarzonalva/.conda/envs/arboreto-env/lib/python3.10/site-packages/distributed/worker.py", line 1252, in heartbeat
    response = await retry_operation(
  File "/home/igarzonalva/.conda/envs/arboreto-env/lib/python3.10/site-packages/distributed/utils_comm.py", line 455, in retry_operation
    return await retry(
  File "/home/igarzonalva/.conda/envs/arboreto-env/lib/python3.10/site-packages/distributed/utils_comm.py", line 434, in retry
    return await coro()
  File "/home/igarzonalva/.conda/envs/arboreto-env/lib/python3.10/site-packages/distributed/core.py", line 1395, in send_recv_from_rpc
    return await send_recv(comm=comm, op=key, **kwargs)
  File "/home/igarzonalva/.conda/envs/arboreto-env/lib/python3.10/site-packages/distributed/core.py", line 1154, in send_recv
    response = await comm.read(deserializers=deserializers)
  File "/home/igarzonalva/.conda/envs/arboreto-env/lib/python3.10/site-packages/distributed/comm/tcp.py", line 236, in read
    convert_stream_closed_error(self, e)
  File "/home/igarzonalva/.conda/envs/arboreto-env/lib/python3.10/site-packages/distributed/comm/tcp.py", line 140, in convert_stream_closed_error
    raise CommClosedError(f"in {obj}: {exc.__class__.__name__}: {exc}") from exc
distributed.comm.core.CommClosedError: in <TCP (closed) ConnectionPool.heartbeat_worker local=tcp://172.16.2.1:34858 remote=tcp://159.237.145.53:44251>: ConnectionResetError: [Errno 104] Connection reset by peer
2025-01-21 05:13:25,401 - distributed.worker - ERROR - Failed to communicate with scheduler during heartbeat.
Traceback (most recent call last):
  File "/home/igarzonalva/.conda/envs/arboreto-env/lib/python3.10/site-packages/tornado/iostream.py", line 861, in _read_to_buffer
    bytes_read = self.read_from_fd(buf)
  File "/home/igarzonalva/.conda/envs/arboreto-env/lib/python3.10/site-packages/tornado/iostream.py", line 1116, in read_from_fd
    return self.socket.recv_into(buf, len(buf))
ConnectionResetError: [Errno 104] Connection reset by peer

The above exception was the direct cause of the following exception:

Traceback (most recent call last):
  File "/home/igarzonalva/.conda/envs/arboreto-env/lib/python3.10/site-packages/distributed/worker.py", line 1252, in heartbeat
    response = await retry_operation(
  File "/home/igarzonalva/.conda/envs/arboreto-env/lib/python3.10/site-packages/distributed/utils_comm.py", line 455, in retry_operation
    return await retry(
  File "/home/igarzonalva/.conda/envs/arboreto-env/lib/python3.10/site-packages/distributed/utils_comm.py", line 434, in retry
    return await coro()
  File "/home/igarzonalva/.conda/envs/arboreto-env/lib/python3.10/site-packages/distributed/core.py", line 1395, in send_recv_from_rpc
    return await send_recv(comm=comm, op=key, **kwargs)
  File "/home/igarzonalva/.conda/envs/arboreto-env/lib/python3.10/site-packages/distributed/core.py", line 1154, in send_recv
    response = await comm.read(deserializers=deserializers)
  File "/home/igarzonalva/.conda/envs/arboreto-env/lib/python3.10/site-packages/distributed/comm/tcp.py", line 236, in read
    convert_stream_closed_error(self, e)
  File "/home/igarzonalva/.conda/envs/arboreto-env/lib/python3.10/site-packages/distributed/comm/tcp.py", line 140, in convert_stream_closed_error
    raise CommClosedError(f"in {obj}: {exc.__class__.__name__}: {exc}") from exc
distributed.comm.core.CommClosedError: in <TCP (closed) ConnectionPool.heartbeat_worker local=tcp://172.16.2.1:34860 remote=tcp://159.237.145.53:44251>: ConnectionResetError: [Errno 104] Connection reset by peer
2025-01-21 05:13:25,409 - distributed.core - INFO - Connection to tcp://159.237.145.53:44251 has been closed.
2025-01-21 05:13:25,409 - distributed.core - INFO - Connection to tcp://159.237.145.53:44251 has been closed.
2025-01-21 05:13:25,411 - distributed.worker - INFO - Stopping worker at tcp://172.16.2.1:38501. Reason: worker-handle-scheduler-connection-broken
2025-01-21 05:13:25,415 - distributed.nanny - INFO - Closing Nanny gracefully at 'tcp://172.16.2.1:43372'. Reason: worker-handle-scheduler-connection-broken
2025-01-21 05:13:25,400 - distributed.worker - ERROR - Failed to communicate with scheduler during heartbeat.
Traceback (most recent call last):
  File "/home/igarzonalva/.conda/envs/arboreto-env/lib/python3.10/site-packages/tornado/iostream.py", line 861, in _read_to_buffer
    bytes_read = self.read_from_fd(buf)
  File "/home/igarzonalva/.conda/envs/arboreto-env/lib/python3.10/site-packages/tornado/iostream.py", line 1116, in read_from_fd
    return self.socket.recv_into(buf, len(buf))
ConnectionResetError: [Errno 104] Connection reset by peer

The above exception was the direct cause of the following exception:

Traceback (most recent call last):
  File "/home/igarzonalva/.conda/envs/arboreto-env/lib/python3.10/site-packages/distributed/worker.py", line 1252, in heartbeat
    response = await retry_operation(
  File "/home/igarzonalva/.conda/envs/arboreto-env/lib/python3.10/site-packages/distributed/utils_comm.py", line 455, in retry_operation
    return await retry(
  File "/home/igarzonalva/.conda/envs/arboreto-env/lib/python3.10/site-packages/distributed/utils_comm.py", line 434, in retry
    return await coro()
  File "/home/igarzonalva/.conda/envs/arboreto-env/lib/python3.10/site-packages/distributed/core.py", line 1395, in send_recv_from_rpc
    return await send_recv(comm=comm, op=key, **kwargs)
  File "/home/igarzonalva/.conda/envs/arboreto-env/lib/python3.10/site-packages/distributed/core.py", line 1154, in send_recv
    response = await comm.read(deserializers=deserializers)
  File "/home/igarzonalva/.conda/envs/arboreto-env/lib/python3.10/site-packages/distributed/comm/tcp.py", line 236, in read
    convert_stream_closed_error(self, e)
  File "/home/igarzonalva/.conda/envs/arboreto-env/lib/python3.10/site-packages/distributed/comm/tcp.py", line 140, in convert_stream_closed_error
    raise CommClosedError(f"in {obj}: {exc.__class__.__name__}: {exc}") from exc
distributed.comm.core.CommClosedError: in <TCP (closed) ConnectionPool.heartbeat_worker local=tcp://172.16.2.1:34864 remote=tcp://159.237.145.53:44251>: ConnectionResetError: [Errno 104] Connection reset by peer
2025-01-21 05:13:25,410 - distributed.worker - INFO - Stopping worker at tcp://172.16.2.1:46673. Reason: worker-handle-scheduler-connection-broken
2025-01-21 05:13:25,416 - distributed.core - INFO - Connection to tcp://159.237.145.53:44251 has been closed.
2025-01-21 05:13:25,417 - distributed.worker - INFO - Stopping worker at tcp://172.16.2.1:35066. Reason: worker-handle-scheduler-connection-broken
2025-01-21 05:13:25,420 - distributed.nanny - INFO - Closing Nanny gracefully at 'tcp://172.16.2.1:45369'. Reason: worker-handle-scheduler-connection-broken
2025-01-21 05:13:25,409 - distributed.core - INFO - Connection to tcp://159.237.145.53:44251 has been closed.
2025-01-21 05:13:25,416 - distributed.worker.state_machine - WARNING - Async instruction for <Task cancelled name="execute('infer_partial_network-e401dfa42f533fb0cf84bad7fd62f303')" coro=<Worker.execute() done, defined at /home/igarzonalva/.conda/envs/arboreto-env/lib/python3.10/site-packages/distributed/worker_state_machine.py:3615>> ended with CancelledError
2025-01-21 05:13:25,421 - distributed.worker.state_machine - WARNING - Async instruction for <Task cancelled name="execute('infer_partial_network-957e34a31ad70b10864e883935aa0fc9')" coro=<Worker.execute() done, defined at /home/igarzonalva/.conda/envs/arboreto-env/lib/python3.10/site-packages/distributed/worker_state_machine.py:3615>> ended with CancelledError
2025-01-21 05:13:25,421 - distributed.nanny - INFO - Closing Nanny gracefully at 'tcp://172.16.2.1:33624'. Reason: worker-handle-scheduler-connection-broken
2025-01-21 05:13:25,421 - distributed.worker - INFO - Stopping worker at tcp://172.16.2.1:39819. Reason: worker-handle-scheduler-connection-broken
2025-01-21 05:13:25,422 - distributed.worker.state_machine - WARNING - Async instruction for <Task cancelled name="execute('infer_partial_network-8099e2f4ebb4caebc2fb81ca89229c92')" coro=<Worker.execute() done, defined at /home/igarzonalva/.conda/envs/arboreto-env/lib/python3.10/site-packages/distributed/worker_state_machine.py:3615>> ended with CancelledError
2025-01-21 05:13:25,426 - distributed.nanny - INFO - Closing Nanny gracefully at 'tcp://172.16.2.1:40576'. Reason: worker-handle-scheduler-connection-broken
2025-01-21 05:13:25,429 - distributed.worker.state_machine - WARNING - Async instruction for <Task cancelled name="execute('infer_partial_network-a45f5e7d3a2eee2ffccd9c10de2d0040')" coro=<Worker.execute() done, defined at /home/igarzonalva/.conda/envs/arboreto-env/lib/python3.10/site-packages/distributed/worker_state_machine.py:3615>> ended with CancelledError
2025-01-21 05:13:26,724 - distributed.nanny - INFO - Worker closed
2025-01-21 05:13:27,378 - distributed.nanny - INFO - Worker closed
2025-01-21 05:13:28,408 - distributed.nanny - INFO - Worker closed
2025-01-21 05:13:29,156 - distributed.nanny - INFO - Worker closed
2025-01-21 05:13:29,380 - distributed.nanny - ERROR - Worker process died unexpectedly
2025-01-21 05:13:30,016 - distributed.nanny - INFO - Closing Nanny at 'tcp://172.16.2.1:33624'. Reason: nanny-close-gracefully
2025-01-21 05:13:30,130 - distributed.nanny - INFO - Closing Nanny at 'tcp://172.16.2.1:45369'. Reason: nanny-close-gracefully
2025-01-21 05:13:30,410 - distributed.nanny - ERROR - Worker process died unexpectedly
2025-01-21 05:13:30,908 - distributed.nanny - INFO - Closing Nanny at 'tcp://172.16.2.1:40576'. Reason: nanny-close-gracefully
2025-01-21 05:13:31,158 - distributed.nanny - ERROR - Worker process died unexpectedly
2025-01-21 05:13:31,814 - distributed.nanny - INFO - Closing Nanny at 'tcp://172.16.2.1:43372'. Reason: nanny-close-gracefully
2025-01-21 05:13:31,815 - distributed.dask_worker - INFO - End worker
